Workbook

Sheet Codebook
A1: XR systematic mapping – extraction codebook for RQ5–RQ7
A3: Research questions
A4: RQ5. In which education levels, subject areas and countries/regions have XR studies on engagement, motivation and satisfaction been conducted?
A5: RQ6. What is the direction, strength and consistency of reported XR effects on learner engagement, motivation and satisfaction, and do they differ by education level, subject area and device type?
A6: RQ7. What is the methodological quality and design rigor of the included studies?
A8: How RQ6 is answered: each study is coded + / 0 / − / Mixed per outcome ("direction"); strength = statistical support, effect size and rigor of the studies behind each direction; consistency = share of measuring studies that agree, computed across studies on the Evidence Map sheet (not coded per paper).
A9: Quality appraisal: Mixed Methods Appraisal Tool (MMAT) 2018, Hong QN et al. Two screening questions, then 5 category-specific criteria; score = number met (0–5).
A10: MMAT item ratings are entered on the "MMAT Appraisal" sheet; the MMAT score and "Overall rigor" in Sheet1 update automatically. For mixed-methods studies the component that provides the RQ6 evidence is appraised. Where a construct fits more than one outcome, the code follows the definitions below (e.g., SAM emotional valence = emotional engagement; enjoyment/interest = motivation; satisfaction/preference/reuse = satisfaction).
A12: RQ | B12: Column in Sheet1 | C12: Definition / allowed values
A13: RQ5 | B13: AR: Country (study site) | C13: Country where the learners were studied (not author affiliation). Multi-country → list all.
A14: RQ5 | B14: AS: Region | C14: Continent derived from country: Africa / Asia / Europe / North America / South America / Oceania / Multi-country.
A15: RQ5 | B15: AT: Education level (ISCED 2011) | C15: Pre-primary / Primary / Lower secondary / Upper secondary / Secondary (unspecified) / Mixed K-12 / Mixed (school-age + adults) / Higher education / Mixed (secondary + post-secondary) / Informal / general public / Not reported.
A16: RQ5 | B16: AU: Learner population | C16: Who provided the data: typical learners, SEN learners (state condition), teachers as evaluators, general public.
A17: RQ5 | B17: AV: Subject area (ISCED-F 2013 broad field) | C17: Broad field of education & training (UNESCO ISCED-F 2013). "Generic / multi-subject" for cross-curricular or life-skills content.
A18: RQ5 | B18: AW: Subject (specific) | C18: Specific topic as reported by the study.
A19: RQ6 | B19: AX: XR type | C19: VR / AR / MR / VR + AR / VR (360°) / non-immersive variants. Record what learners actually used.
A20: RQ6 | B20: AY: Device category | C20: HMD (immersive) / Handheld (mobile/tablet) / Desktop / CAVE or projection / Web-based / None (mock-up) / Not reported. Used as the device-type moderator for RQ6.
A21: RQ6 | B21: AZ: Device (specific) | C21: Hardware/platform as reported.
A22: RQ6 | B22: BA: Comparison condition | C22: None / Traditional teaching / Non-immersive digital / Other XR / Traditional + non-immersive.
A23: RQ6 | B23: BB: Engagement effect | C23: + positive / 0 no difference / − negative / Mixed / Unclear (measured but direction not reported) / Not measured. Engagement = behavioural, cognitive or emotional involvement (participation, attention, flow, concentration, active discussion).
... A43: Admin | B43: BV: Verification flags | C43: Open issues for the full-text pass.

Sheet Evidence Map
A1: Evidence map – every count is a live formula on Sheet1
A2: Sets: Mapping corpus = all studies except retracted (E1). Empirical = Core + Sensitivity. Core = basic-education learners with E/M/S data (primary synthesis).
A4: Table 0. Eligibility flow for RQ5–RQ7
A5: Set | B5: Studies
A6: Mapping corpus (RQ1–RQ4 published set) | B6: =COUNTA(Sheet1!$A$2:$A$200) -> 45
A7: Excluded – E1 retracted | B7: =COUNTIFS(Sheet1!$BT$2:$BT$200,"E1*") -> 1
A8: Mapping corpus used for RQ5 | B8: =B6-B7 -> 44
A9: Excluded – E2 no learner data | B9: =COUNTIFS(Sheet1!$BT$2:$BT$200,"E2*") -> 8
A10: Excluded – E3 no E/M/S outcome measured | B10: =COUNTIFS(Sheet1!$BT$2:$BT$200,"E3*") -> 1
A11: Excluded – E4 teacher-only data | B11: =COUNTIFS(Sheet1!$BT$2:$BT$200,"E4*") -> 2
A12: Excluded – E5 no real XR exposure | B12: =COUNTIFS(Sheet1!$BT$2:$BT$200,"E5*") -> 1
A13: Empirical studies (RQ7 appraisal) | B13: =COUNTIFS(Sheet1!$BS$2:$BS$200,"Core")+COUNTIFS(Sheet1!$BS$2:$BS$200,"Sensitivity") -> 32
A14: Sensitivity (outside basic education) | B14: =COUNTIFS(Sheet1!$BS$2:$BS$200,"Sensitivity") -> 11
A15: Core synthesis set (RQ6) | B15: =COUNTIFS(Sheet1!$BS$2:$BS$200,"Core") -> 21
A17: Table 6a. RQ6 – Direction and consistency of effects, CORE set (basic education)
A18: Outcome | B18: + | C18: Mixed | D18: Unclear | E18: 0 | F18: − | G18: Studies measuring | H18: % positive (consistency) | I18: + from Moderate/High-rigor
A19: Engagement | B19: =COUNTIFS(Sheet1!$BB$2:$BB$200,"+",Sheet1!$BS$2:$BS$200,"Core") -> 7 | C19: =COUNTIFS(Sheet1!$BB$2:$BB$200,"Mixed",Sheet1!$BS$2:$BS$200,"Core") -> 1 | D19: =COUNTIFS(Sheet1!$BB$2:$BB$200,"Unclear",Sheet1!$BS$2:$BS$200,"Core") -> 1 | E19: =COUNTIFS(Sheet1!$BB$2:$BB$200,"0",Sheet1!$BS$2:$BS$200,"Core") -> 0 | F19: =COUNTIFS(Sheet1!$BB$2:$BB$200,"−",Sheet1!$BS$2:$BS$200,"Core") -> 0 | G19: =SUM(B19:F19) -> 9 | H19: =IF(G19=0,"-",B19/G19) -> 0.77777778 | I19: =COUNTIFS(Sheet1!$BB$2:$BB$200,"+",Sheet1!$BS$2:$BS$200,"Core",Sheet1!$BP$2:$BP$200,"Moderate")+COUNTIFS(Sheet1!$BB$2:$BB$200,"+",Sheet1!$BS$2:$BS$200,"Core",Sheet1!$BP$2:$BP$200,"High") -> 1
A20: Motivation | B20: =COUNTIFS(Sheet1!$BC$2:$BC$200,"+",Sheet1!$BS$2:$BS$200,"Core") -> 15 | C20: =COUNTIFS(Sheet1!$BC$2:$BC$200,"Mixed",Sheet1!$BS$2:$BS$200,"Core") -> 0 | D20: =COUNTIFS(Sheet1!$BC$2:$BC$200,"Unclear",Sheet1!$BS$2:$BS$200,"Core") -> 0 | E20: =COUNTIFS(Sheet1!$BC$2:$BC$200,"0",Sheet1!$BS$2:$BS$200,"Core") -> 0 | F20: =COUNTIFS(Sheet1!$BC$2:$BC$200,"−",Sheet1!$BS$2:$BS$200,"Core") -> 0 | G20: =SUM(B20:F20) -> 15 | H20: =IF(G20=0,"-",B20/G20) -> 1 | I20: =COUNTIFS(Sheet1!$BC$2:$BC$200,"+",Sheet1!$BS$2:$BS$200,"Core",Sheet1!$BP$2:$BP$200,"Moderate")+COUNTIFS(Sheet1!$BC$2:$BC$200,"+",Sheet1!$BS$2:$BS$200,"Core",Sheet1!$BP$2:$BP$200,"High") -> 3
A21: Satisfaction | B21: =COUNTIFS(Sheet1!$BD$2:$BD$200,"+",Sheet1!$BS$2:$BS$200,"Core") -> 13 | C21: =COUNTIFS(Sheet1!$BD$2:$BD$200,"Mixed",Sheet1!$BS$2:$BS$200,"Core") -> 0 | D21: =COUNTIFS(Sheet1!$BD$2:$BD$200,"Unclear",Sheet1!$BS$2:$BS$200,"Core") -> 1 | E21: =COUNTIFS(Sheet1!$BD$2:$BD$200,"0",Sheet1!$BS$2:$BS$200,"Core") -> 0 | F21: =COUNTIFS(Sheet1!$BD$2:$BD$200,"−",Sheet1!$BS$2:$BS$200,"Core") -> 0 | G21: =SUM(B21:F21) -> 14 | H21: =IF(G21=0,"-",B21/G21) -> 0.92857143 | I21: =COUNTIFS(Sheet1!$BD$2:$BD$200,"+",Sheet1!$BS$2:$BS$200,"Core",Sheet1!$BP$2:$BP$200,"Moderate")+COUNTIFS(Sheet1!$BD$2:$BD$200,"+",Sheet1!$BS$2:$BS$200,"Core",Sheet1!$BP$2:$BP$200,"High") -> 2
A23: Table 6b. RQ6 – Direction and consistency, ALL empirical studies (Core + Sensitivity)
A24: Outcome | B24: + | C24: Mixed | D24: Unclear | E24: 0 | F24: − | G24: Studies measuring | H24: % positive (consistency) | I24: + from Moderate/High-rigor
A25: Engagement | B25: =(COUNTIFS(Sheet1!$BB$2:$BB$200,"+",Sheet1!$BS$2:$BS$200,"Core")+COUNTIFS(Sheet1!$BB$2:$BB$200,"+",Sheet1!$BS$2:$BS$200,"Sensitivity")) -> 11 | C25: =(COUNTIFS(Sheet1!$BB$2:$BB$200,"Mixed",Sheet1!$BS$2:$BS$200,"Core")+COUNTIFS(Sheet1!$BB$2:$BB$200,"Mixed",Sheet1!$BS$2:$BS$200,"Sensitivity")) -> 1 | D25: =(COUNTIFS(Sheet1!$BB$2:$BB$200,"Unclear",Sheet1!$BS$2:$BS$200,"Core")+COUNTIFS(Sheet1!$BB$2:$BB$200,"Unclear",Sheet1!$BS$2:$BS$200,"Sensitivity")) -> 1 | E25: =(COUNTIFS(Sheet1!$BB$2:$BB$200,"0",Sheet1!$BS$2:$BS$200,"Core")+COUNTIFS(Sheet1!$BB$2:$BB$200,"0",Sheet1!$BS$2:$BS$200,"Sensitivity")) -> 0 | F25: =(COUNTIFS(Sheet1!$BB$2:$BB$200,"−",Sheet1!$BS$2:$BS$200,"Core")+COUNTIFS(Sheet1!$BB$2:$BB$200,"−",Sheet1!$BS$2:$BS$200,"Sensitivity")) -> 0 | G25: =SUM(B25:F25) -> 13 | H25: =IF(G25=0,"-",B25/G25) -> 0.84615385 | I25: =COUNTIFS(Sheet1!$BB$2:$BB$200,"+",Sheet1!$BS$2:$BS$200,"<>Excluded",Sheet1!$BP$2:$BP$200,"Moderate")+COUNTIFS(Sheet1!$BB$2:$BB$200,"+",Sheet1!$BS$2:$BS$200,"<>Excluded",Sheet1!$BP$2:$BP$200,"High") -> 1
A26: Motivation | B26: =(COUNTIFS(Sheet1!$BC$2:$BC$200,"+",Sheet1!$BS$2:$BS$200,"Core")+COUNTIFS(Sheet1!$BC$2:$BC$200,"+",Sheet1!$BS$2:$BS$200,"Sensitivity")) -> 22 | C26: =(COUNTIFS(Sheet1!$BC$2:$BC$200,"Mixed",Sheet1!$BS$2:$BS$200,"Core")+COUNTIFS(Sheet1!$BC$2:$BC$200,"Mixed",Sheet1!$BS$2:$BS$200,"Sensitivity")) -> 1 | D26: =(COUNTIFS(Sheet1!$BC$2:$BC$200,"Unclear",Sheet1!$BS$2:$BS$200,"Core")+COUNTIFS(Sheet1!$BC$2:$BC$200,"Unclear",Sheet1!$BS$2:$BS$200,"Sensitivity")) -> 1 | E26: =(COUNTIFS(Sheet1!$BC$2:$BC$200,"0",Sheet1!$BS$2:$BS$200,"Core")+COUNTIFS(Sheet1!$BC$2:$BC$200,"0",Sheet1!$BS$2:$BS$200,"Sensitivity")) -> 0 | F26: =(COUNTIFS(Sheet1!$BC$2:$BC$200,"−",Sheet1!$BS$2:$BS$200,"Core")+COUNTIFS(Sheet1!$BC$2:$BC$200,"−",Sheet1!$BS$2:$BS$200,"Sensitivity")) -> 0 | G26: =SUM(B26:F26) -> 24 | H26: =IF(G26=0,"-",B26/G26) -> 0.91666667 | I26: =COUNTIFS(Sheet1!$BC$2:$BC$200,"+",Sheet1!$BS$2:$BS$200,"<>Excluded",Sheet1!$BP$2:$BP$200,"Moderate")+COUNTIFS(Sheet1!$BC$2:$BC$200,"+",Sheet1!$BS$2:$BS$200,"<>Excluded",Sheet1!$BP$2:$BP$200,"High") -> 4
A27: Satisfaction | B27: =(COUNTIFS(Sheet1!$BD$2:$BD$200,"+",Sheet1!$BS$2:$BS$200,"Core")+COUNTIFS(Sheet1!$BD$2:$BD$200,"+",Sheet1!$BS$2:$BS$200,"Sensitivity")) -> 21 | C27: =(COUNTIFS(Sheet1!$BD$2:$BD$200,"Mixed",Sheet1!$BS$2:$BS$200,"Core")+COUNTIFS(Sheet1!$BD$2:$BD$200,"Mixed",Sheet1!$BS$2:$BS$200,"Sensitivity")) -> 0 | D27: =(COUNTIFS(Sheet1!$BD$2:$BD$200,"Unclear",Sheet1!$BS$2:$BS$200,"Core")+COUNTIFS(Sheet1!$BD$2:$BD$200,"Unclear",Sheet1!$BS$2:$BS$200,"Sensitivity")) -> 1 | E27: =(COUNTIFS(Sheet1!$BD$2:$BD$200,"0",Sheet1!$BS$2:$BS$200,"Core")+COUNTIFS(Sheet1!$BD$2:$BD$200,"0",Sheet1!$BS$2:$BS$200,"Sensitivity")) -> 0 | F27: =(COUNTIFS(Sheet1!$BD$2:$BD$200,"−",Sheet1!$BS$2:$BS$200,"Core")+COUNTIFS(Sheet1!$BD$2:$BD$200,"−",Sheet1!$BS$2:$BS$200,"Sensitivity")) -> 0 | G27: =SUM(B27:F27) -> 22 | H27: =IF(G27=0,"-",B27/G27) -> 0.95454545 | I27: =COUNTIFS(Sheet1!$BD$2:$BD$200,"+",Sheet1!$BS$2:$BS$200,"<>Excluded",Sheet1!$BP$2:$BP$200,"Moderate")+COUNTIFS(Sheet1!$BD$2:$BD$200,"+",Sheet1!$BS$2:$BS$200,"<>Excluded",Sheet1!$BP$2:$BP$200,"High") -> 4
A29: RQ6 (Core set). Effects by education level [positive / measured]
A30: education level | B30: Core studies | C30: Engagement + | D30: Engagement measured | E30: Motivation + | F30: Motivation measured | G30: Satisfaction + | H30: Satisfaction measured
A31: Primary | B31: =COUNTIFS(Sheet1!$AT$2:$AT$200,A31,Sheet1!$BS$2:$BS$200,"Core") -> 4 | C31: =COUNTIFS(Sheet1!$AT$2:$AT$200,A31,Sheet1!$BS$2:$BS$200,"Core",Sheet1!$BB$2:$BB$200,"+") -> 1 | D31: =COUNTIFS(Sheet1!$AT$2:$AT$200,A31,Sheet1!$BS$2:$BS$200,"Core",Sheet1!$BB$2:$BB$200,"<>Not measured",Sheet1!$BB$2:$BB$200,"<>") -> 1 | E31: =COUNTIFS(Sheet1!$AT$2:$AT$200,A31,Sheet1!$BS$2:$BS$200,"Core",Sheet1!$BC$2:$BC$200,"+") -> 4 | F31: =COUNTIFS(Sheet1!$AT$2:$AT$200,A31,Sheet1!$BS$2:$BS$200,"Core",Sheet1!$BC$2:$BC$200,"<>Not measured",Sheet1!$BC$2:$BC$200,"<>") -> 4 | G31: =COUNTIFS(Sheet1!$AT$2:$AT$200,A31,Sheet1!$BS$2:$BS$200,"Core",Sheet1!$BD$2:$BD$200,"+") -> 3 | H31: =COUNTIFS(Sheet1!$AT$2:$AT$200,A31,Sheet1!$BS$2:$BS$200,"Core",Sheet1!$BD$2:$BD$200,"<>Not measured",Sheet1!$BD$2:$BD$200,"<>") -> 3
A32: Lower secondary | B32: =COUNTIFS(Sheet1!$AT$2:$AT$200,A32,Sheet1!$BS$2:$BS$200,"Core") -> 4 | C32: =COUNTIFS(Sheet1!$AT$2:$AT$200,A32,Sheet1!$BS$2:$BS$200,"Core",Sheet1!$BB$2:$BB$200,"+") -> 1 | D32: =COUNTIFS(Sheet1!$AT$2:$AT$200,A32,Sheet1!$BS$2:$BS$200,"Core",Sheet1!$BB$2:$BB$200,"<>Not measured",Sheet1!$BB$2:$BB$200,"<>") -> 2 | E32: =COUNTIFS(Sheet1!$AT$2:$AT$200,A32,Sheet1!$BS$2:$BS$200,"Core",Sheet1!$BC$2:$BC$200,"+") -> 3 | F32: =COUNTIFS(Sheet1!$AT$2:$AT$200,A32,Sheet1!$BS$2:$BS$200,"Core",Sheet1!$BC$2:$BC$200,"<>Not measured",Sheet1!$BC$2:$BC$200,"<>") -> 3 | G32: =COUNTIFS(Sheet1!$AT$2:$AT$200,A32,Sheet1!$BS$2:$BS$200,"Core",Sheet1!$BD$2:$BD$200,"+") -> 1 | H32: =COUNTIFS(Sheet1!$AT$2:$AT$200,A32,Sheet1!$BS$2:$BS$200,"Core",Sheet1!$BD$2:$BD$200,"<>Not measured",Sheet1!$BD$2:$BD$200,"<>") -> 2
A33: Upper secondary | B33: =COUNTIFS(Sheet1!$AT$2:$AT$200,A33,Sheet1!$BS$2:$BS$200,"Core") -> 2 | C33: =COUNTIFS(Sheet1!$AT$2:$AT$200,A33,Sheet1!$BS$2:$BS$200,"Core",Sheet1!$BB$2:$BB$200,"+") -> 0 | D33: =COUNTIFS(Sheet1!$AT$2:$AT$200,A33,Sheet1!$BS$2:$BS$200,"Core",Sheet1!$BB$2:$BB$200,"<>Not measured",Sheet1!$BB$2:$BB$200,"<>") -> 0 | E33: =COUNTIFS(Sheet1!$AT$2:$AT$200,A33,Sheet1!$BS$2:$BS$200,"Core",Sheet1!$BC$2:$BC$200,"+") -> 1 | F33: =COUNTIFS(Sheet1!$AT$2:$AT$200,A33,Sheet1!$BS$2:$BS$200,"Core",Sheet1!$BC$2:$BC$200,"<>Not measured",Sheet1!$BC$2:$BC$200,"<>") -> 1 | G33: =COUNTIFS(Sheet1!$AT$2:$AT$200,A33,Sheet1!$BS$2:$BS$200,"Core",Sheet1!$BD$2:$BD$200,"+") -> 1 | H33: =COUNTIFS(Sheet1!$AT$2:$AT$200,A33,Sheet1!$BS$2:$BS$200,"Core",Sheet1!$BD$2:$BD$200,"<>Not measured",Sheet1!$BD$2:$BD$200,"<>") -> 1
A34: Secondary (unspecified) | B34: =COUNTIFS(Sheet1!$AT$2:$AT$200,A34,Sheet1!$BS$2:$BS$200,"Core") -> 3 | C34: =COUNTIFS(Sheet1!$AT$2:$AT$200,A34,Sheet1!$BS$2:$BS$200,"Core",Sheet1!$BB$2:$BB$200,"+") -> 1 | D34: =COUNTIFS(Sheet1!$AT$2:$AT$200,A34,Sheet1!$BS$2:$BS$200,"Core",Sheet1!$BB$2:$BB$200,"<>Not measured",Sheet1!$BB$2:$BB$200,"<>") -> 2 | E34: =COUNTIFS(Sheet1!$AT$2:$AT$200,A34,Sheet1!$BS$2:$BS$200,"Core",Sheet1!$BC$2:$BC$200,"+") -> 2 | F34: =COUNTIFS(Sheet1!$AT$2:$AT$200,A34,Sheet1!$BS$2:$BS$200,"Core",Sheet1!$BC$2:$BC$200,"<>Not measured",Sheet1!$BC$2:$BC$200,"<>") -> 2 | G34: =COUNTIFS(Sheet1!$AT$2:$AT$200,A34,Sheet1!$BS$2:$BS$200,"Core",Sheet1!$BD$2:$BD$200,"+") -> 3 | H34: =COUNTIFS(Sheet1!$AT$2:$AT$200,A34,Sheet1!$BS$2:$BS$200,"Core",Sheet1!$BD$2:$BD$200,"<>Not measured",Sheet1!$BD$2:$BD$200,"<>") -> 3
A35: Mixed K-12 | B35: =COUNTIFS(Sheet1!$AT$2:$AT$200,A35,Sheet1!$BS$2:$BS$200,"Core") -> 4 | C35: =COUNTIFS(Sheet1!$AT$2:$AT$200,A35,Sheet1!$BS$2:$BS$200,"Core",Sheet1!$BB$2:$BB$200,"+") -> 3 | D35: =COUNTIFS(Sheet1!$AT$2:$AT$200,A35,Sheet1!$BS$2:$BS$200,"Core",Sheet1!$BB$2:$BB$200,"<>Not measured",Sheet1!$BB$2:$BB$200,"<>") -> 3 | E35: =COUNTIFS(Sheet1!$AT$2:$AT$200,A35,Sheet1!$BS$2:$BS$200,"Core",Sheet1!$BC$2:$BC$200,"+") -> 2 | F35: =COUNTIFS(Sheet1!$AT$2:$AT$200,A35,Sheet1!$BS$2:$BS$200,"Core",Sheet1!$BC$2:$BC$200,"<>Not measured",Sheet1!$BC$2:$BC$200,"<>") -> 2 | G35: =COUNTIFS(Sheet1!$AT$2:$AT$200,A35,Sheet1!$BS$2:$BS$200,"Core",Sheet1!$BD$2:$BD$200,"+") -> 1 | H35: =COUNTIFS(Sheet1!$AT$2:$AT$200,A35,Sheet1!$BS$2:$BS$200,"Core",Sheet1!$BD$2:$BD$200,"<>Not measured",Sheet1!$BD$2:$BD$200,"<>") -> 1
A36: Mixed (school-age + adults) | B36: =COUNTIFS(Sheet1!$AT$2:$AT$200,A36,Sheet1!$BS$2:$BS$200,"Core") -> 1 | C36: =COUNTIFS(Sheet1!$AT$2:$AT$200,A36,Sheet1!$BS$2:$BS$200,"Core",Sheet1!$BB$2:$BB$200,"+") -> 0 | D36: =COUNTIFS(Sheet1!$AT$2:$AT$200,A36,Sheet1!$BS$2:$BS$200,"Core",Sheet1!$BB$2:$BB$200,"<>Not measured",Sheet1!$BB$2:$BB$200,"<>") -> 0 | E36: =COUNTIFS(Sheet1!$AT$2:$AT$200,A36,Sheet1!$BS$2:$BS$200,"Core",Sheet1!$BC$2:$BC$200,"+") -> 0 | F36: =COUNTIFS(Sheet1!$AT$2:$AT$200,A36,Sheet1!$BS$2:$BS$200,"Core",Sheet1!$BC$2:$BC$200,"<>Not measured",Sheet1!$BC$2:$BC$200,"<>") -> 0 | G36: =COUNTIFS(Sheet1!$AT$2:$AT$200,A36,Sheet1!$BS$2:$BS$200,"Core",Sheet1!$BD$2:$BD$200,"+") -> 1 | H36: =COUNTIFS(Sheet1!$AT$2:$AT$200,A36,Sheet1!$BS$2:$BS$200,"Core",Sheet1!$BD$2:$BD$200,"<>Not measured",Sheet1!$BD$2:$BD$200,"<>") -> 1
A37: Mixed (secondary + post-secondary) | B37: =COUNTIFS(Sheet1!$AT$2:$AT$200,A37,Sheet1!$BS$2:$BS$200,"Core") -> 2 | C37: =COUNTIFS(Sheet1!$AT$2:$AT$200,A37,Sheet1!$BS$2:$BS$200,"Core",Sheet1!$BB$2:$BB$200,"+") -> 1 | D37: =COUNTIFS(Sheet1!$AT$2:$AT$200,A37,Sheet1!$BS$2:$BS$200,"Core",Sheet1!$BB$2:$BB$200,"<>Not measured",Sheet1!$BB$2:$BB$200,"<>") -> 1 | E37: =COUNTIFS(Sheet1!$AT$2:$AT$200,A37,Sheet1!$BS$2:$BS$200,"Core",Sheet1!$BC$2:$BC$200,"+") -> 2 | F37: =COUNTIFS(Sheet1!$AT$2:$AT$200,A37,Sheet1!$BS$2:$BS$200,"Core",Sheet1!$BC$2:$BC$200,"<>Not measured",Sheet1!$BC$2:$BC$200,"<>") -> 2 | G37: =COUNTIFS(Sheet1!$AT$2:$AT$200,A37,Sheet1!$BS$2:$BS$200,"Core",Sheet1!$BD$2:$BD$200,"+") -> 2 | H37: =COUNTIFS(Sheet1!$AT$2:$AT$200,A37,Sheet1!$BS$2:$BS$200,"Core",Sheet1!$BD$2:$BD$200,"<>Not measured",Sheet1!$BD$2:$BD$200,"<>") -> 2
A38: Not reported | B38: =COUNTIFS(Sheet1!$AT$2:$AT$200,A38,Sheet1!$BS$2:$BS$200,"Core") -> 1 | C38: =COUNTIFS(Sheet1!$AT$2:$AT$200,A38,Sheet1!$BS$2:$BS$200,"Core",Sheet1!$BB$2:$BB$200,"+") -> 0 | D38: =COUNTIFS(Sheet1!$AT$2:$AT$200,A38,Sheet1!$BS$2:$BS$200,"Core",Sheet1!$BB$2:$BB$200,"<>Not measured",Sheet1!$BB$2:$BB$200,"<>") -> 0 | E38: =COUNTIFS(Sheet1!$AT$2:$AT$200,A38,Sheet1!$BS$2:$BS$200,"Core",Sheet1!$BC$2:$BC$200,"+") -> 1 | F38: =COUNTIFS(Sheet1!$AT$2:$AT$200,A38,Sheet1!$BS$2:$BS$200,"Core",Sheet1!$BC$2:$BC$200,"<>Not measured",Sheet1!$BC$2:$BC$200,"<>") -> 1 | G38: =COUNTIFS(Sheet1!$AT$2:$AT$200,A38,Sheet1!$BS$2:$BS$200,"Core",Sheet1!$BD$2:$BD$200,"+") -> 1 | H38: =COUNTIFS(Sheet1!$AT$2:$AT$200,A38,Sheet1!$BS$2:$BS$200,"Core",Sheet1!$BD$2:$BD$200,"<>Not measured",Sheet1!$BD$2:$BD$200,"<>") -> 1
A40: RQ6 (Core set). Effects by device category [positive / measured]
A41: device category | B41: Core studies | C41: Engagement + | D41: Engagement measured | E41: Motivation + | F41: Motivation measured | G41: Satisfaction + | H41: Satisfaction measured
A42: HMD (immersive) | B42: =COUNTIFS(Sheet1!$AY$2:$AY$200,A42,Sheet1!$BS$2:$BS$200,"Core") -> 10 | C42: =COUNTIFS(Sheet1!$AY$2:$AY$200,A42,Sheet1!$BS$2:$BS$200,"Core",Sheet1!$BB$2:$BB$200,"+") -> 5 | D42: =COUNTIFS(Sheet1!$AY$2:$AY$200,A42,Sheet1!$BS$2:$BS$200,"Core",Sheet1!$BB$2:$BB$200,"<>Not measured",Sheet1!$BB$2:$BB$200,"<>") -> 5 | E42: =COUNTIFS(Sheet1!$AY$2:$AY$200,A42,Sheet1!$BS$2:$BS$200,"Core",Sheet1!$BC$2:$BC$200,"+") -> 8 | F42: =COUNTIFS(Sheet1!$AY$2:$AY$200,A42,Sheet1!$BS$2:$BS$200,"Core",Sheet1!$BC$2:$BC$200,"<>Not measured",Sheet1!$BC$2:$BC$200,"<>") -> 8 | G42: =COUNTIFS(Sheet1!$AY$2:$AY$200,A42,Sheet1!$BS$2:$BS$200,"Core",Sheet1!$BD$2:$BD$200,"+") -> 6 | H42: =COUNTIFS(Sheet1!$AY$2:$AY$200,A42,Sheet1!$BS$2:$BS$200,"Core",Sheet1!$BD$2:$BD$200,"<>Not measured",Sheet1!$BD$2:$BD$200,"<>") -> 6
A43: Handheld (mobile/tablet) | B43: =COUNTIFS(Sheet1!$AY$2:$AY$200,A43,Sheet1!$BS$2:$BS$200,"Core") -> 2 | C43: =COUNTIFS(Sheet1!$AY$2:$AY$200,A43,Sheet1!$BS$2:$BS$200,"Core",Sheet1!$BB$2:$BB$200,"+") -> 0 | D43: =COUNTIFS(Sheet1!$AY$2:$AY$200,A43,Sheet1!$BS$2:$BS$200,"Core",Sheet1!$BB$2:$BB$200,"<>Not measured",Sheet1!$BB$2:$BB$200,"<>") -> 0 | E43: =COUNTIFS(Sheet1!$AY$2:$AY$200,A43,Sheet1!$BS$2:$BS$200,"Core",Sheet1!$BC$2:$BC$200,"+") -> 1 | F43: =COUNTIFS(Sheet1!$AY$2:$AY$200,A43,Sheet1!$BS$2:$BS$200,"Core",Sheet1!$BC$2:$BC$200,"<>Not measured",Sheet1!$BC$2:$BC$200,"<>") -> 1 | G43: =COUNTIFS(Sheet1!$AY$2:$AY$200,A43,Sheet1!$BS$2:$BS$200,"Core",Sheet1!$BD$2:$BD$200,"+") -> 2 | H43: =COUNTIFS(Sheet1!$AY$2:$AY$200,A43,Sheet1!$BS$2:$BS$200,"Core",Sheet1!$BD$2:$BD$200,"<>Not measured",Sheet1!$BD$2:$BD$200,"<>") -> 2
A44: Desktop | B44: =COUNTIFS(Sheet1!$AY$2:$AY$200,A44,Sheet1!$BS$2:$BS$200,"Core") -> 4 | C44: =COUNTIFS(Sheet1!$AY$2:$AY$200,A44,Sheet1!$BS$2:$BS$200,"Core",Sheet1!$BB$2:$BB$200,"+") -> 0 | D44: =COUNTIFS(Sheet1!$AY$2:$AY$200,A44,Sheet1!$BS$2:$BS$200,"Core",Sheet1!$BB$2:$BB$200,"<>Not measured",Sheet1!$BB$2:$BB$200,"<>") -> 1 | E44: =COUNTIFS(Sheet1!$AY$2:$AY$200,A44,Sheet1!$BS$2:$BS$200,"Core",Sheet1!$BC$2:$BC$200,"+") -> 3 | F44: =COUNTIFS(Sheet1!$AY$2:$AY$200,A44,Sheet1!$BS$2:$BS$200,"Core",Sheet1!$BC$2:$BC$200,"<>Not measured",Sheet1!$BC$2:$BC$200,"<>") -> 3 | G44: =COUNTIFS(Sheet1!$AY$2:$AY$200,A44,Sheet1!$BS$2:$BS$200,"Core",Sheet1!$BD$2:$BD$200,"+") -> 3 | H44: =COUNTIFS(Sheet1!$AY$2:$AY$200,A44,Sheet1!$BS$2:$BS$200,"Core",Sheet1!$BD$2:$BD$200,"<>Not measured",Sheet1!$BD$2:$BD$200,"<>") -> 3
A45: CAVE / projection | B45: =COUNTIFS(Sheet1!$AY$2:$AY$200,A45,Sheet1!$BS$2:$BS$200,"Core") -> 2 | C45: =COUNTIFS(Sheet1!$AY$2:$AY$200,A45,Sheet1!$BS$2:$BS$200,"Core",Sheet1!$BB$2:$BB$200,"+") -> 2 | D45: =COUNTIFS(Sheet1!$AY$2:$AY$200,A45,Sheet1!$BS$2:$BS$200,"Core",Sheet1!$BB$2:$BB$200,"<>Not measured",Sheet1!$BB$2:$BB$200,"<>") -> 2 | E45: =COUNTIFS(Sheet1!$AY$2:$AY$200,A45,Sheet1!$BS$2:$BS$200,"Core",Sheet1!$BC$2:$BC$200,"+") -> 1 | F45: =COUNTIFS(Sheet1!$AY$2:$AY$200,A45,Sheet1!$BS$2:$BS$200,"Core",Sheet1!$BC$2:$BC$200,"<>Not measured",Sheet1!$BC$2:$BC$200,"<>") -> 1 | G45: =COUNTIFS(Sheet1!$AY$2:$AY$200,A45,Sheet1!$BS$2:$BS$200,"Core",Sheet1!$BD$2:$BD$200,"+") -> 0 | H45: =COUNTIFS(Sheet1!$AY$2:$AY$200,A45,Sheet1!$BS$2:$BS$200,"Core",Sheet1!$BD$2:$BD$200,"<>Not measured",Sheet1!$BD$2:$BD$200,"<>") -> 0
...

Sheet Charts
A1: Figures for RQ5–RQ7 (native Excel charts linked to the Evidence Map sheet – they update automatically)

Sheet MMAT Appraisal
A1: New num | B1: Title | C1: MMAT category | D1: S1 Clear research questions? | E1: S2 Data address the RQs? | F1: Criterion 1 | G1: Criterion 2 | H1: Criterion 3 | I1: Criterion 4 | J1: Criterion 5 | K1: Score (Yes count) | L1: Rationale
A2: 1 | B2: Transforming Secondary School Chemistry Learning with Virtual Reality | C2: Quantitative descriptive | D2: Yes | E2: Yes | F2: Yes | G2: Can't tell | H2: No | I2: Can't tell | J2: Yes | K2: =IF(OR(D2<>"Yes",E2<>"Yes"),"",COUNTIF(F2:J2,"Yes")) -> 2 | L2: 4.1 students from one chemistry class = target group; 4.2 single class, convenience; 4.3 SUS items modified without re-validation; 4.4 response rate not reported; 4.5 descriptive SUS scoring appropriate.
A3: 2 | B3: Development of an immersive virtual reality system for learning about plants in primary education: evaluation of teachers’ perceptions and learners’ flow experiences and learning attitudes | C3: Quantitative descriptive | D3: Yes | E3: Yes | F3: Yes | G3: Can't tell | H3: Yes | I3: Can't tell | J3: Yes | K3: =IF(OR(D3<>"Yes",E3<>"Yes"),"",COUNTIF(F3:J3,"Yes")) -> 3 | L3: Student survey component appraised. 4.1 grade-5 pupils = target; 4.2 recruitment/school not described; 4.3 adapted validated scales with α reported (control α = .54 low); 4.4 completion not reported; 4.5 RM-ANOVA + regression appropriate.
A4: 3 | B4: PlutoAR: a scalable marker-based augmented reality application for interactive and inclusive education | C4: Quantitative descriptive | D4: Yes | E4: Yes | F4: No | G4: No | H4: Can't tell | I4: Can't tell | J4: Yes | K4: =IF(OR(D4<>"Yes",E4<>"Yes"),"",COUNTIF(F4:J4,"Yes")) -> 1 | L4: 4.1 convenience sample at school visits and public events, ages 10–45 pooled; 4.2 not representative of K-10 target; 4.3 SUS standard but satisfaction is single item; 4.4 not reported; 4.5 descriptive appropriate.
A5: 4 | B5: Inclusive Learning through Immersive Virtual Reality and Semantic Embodied Conversational Agent: A case study in children with autism; [Aprendizaje Inclusivo mediante Realidad Virtual Inmersiva y Agente Conversacional Semántico Encarnado: Un caso de estudio en niños con autismo] | C5: Quantitative descriptive | D5: Yes | E5: Yes | F5: Yes | G5: No | H5: Can't tell | I5: Can't tell | J5: Yes | K5: =IF(OR(D5<>"Yes",E5<>"Yes"),"",COUNTIF(F5:J5,"Yes")) -> 2 | L5: 4.1 children with autism = target; 4.2 snowball via one parent network, n = 10; 4.3 adapted SAM, parent-administered test without baseline; 4.4 not reported; 4.5 descriptive appropriate.
A6: 5 | B6: Evaluation User Acceptance of Mobile Virtual Reality Application for English Learning | C6: Quantitative descriptive | D6: Yes | E6: Yes | F6: Yes | G6: Can't tell | H6: Can't tell | I6: Can't tell | J6: Yes | K6: =IF(OR(D6<>"Yes",E6<>"Yes"),"",COUNTIF(F6:J6,"Yes")) -> 2 | L6: 4.1 high-school English learners = target; 4.2 sampling not described; 4.3 adopted TAM items, enjoyment/motivation single items, no reliability; 4.4 not reported; 4.5 descriptive appropriate.
A7: 6 | B7: Implementation of Prototype Environment of Virtual Reality Platform for Virtual Lab (Use case of ESL) | C7: Not appraisable (no empirical learner study) | D7: No | E7: No | K7: =IF(OR(D7<>"Yes",E7<>"Yes"),"",COUNTIF(F7:J7,"Yes")) | L7: Technical latency test only; no learner data.
A8: 7 | B8: Comparison and enhancement of VR water cycle guide applications | C8: Quantitative descriptive | D8: Yes | E8: Yes | F8: Can't tell | G8: Can't tell | H8: No | I8: Can't tell | J8: Can't tell | K8: =IF(OR(D8<>"Yes",E8<>"Yes"),"",COUNTIF(F8:J8,"Yes")) -> 0 | L8: 4.1/4.2 'multiple schools', no sampling or N; 4.3 author-made yes/no items; 4.4 not reported; 4.5 only bar-chart percentages without N.
A9: 8 | B9: User Interface for an Immersive Virtual Reality Greenhouse for Training Precision Agriculture | C9: Not appraisable (no empirical learner study) | D9: Yes | E9: No | K9: =IF(OR(D9<>"Yes",E9<>"Yes"),"",COUNTIF(F9:J9,"Yes")) | L9: Design paper; no user evaluation.
A10: 9 | B10: Work-in-Progress-GeoForge: Integrating Virtual Reality and a Personalized Website to Foster Collaboration in Middle School Science | C10: Qualitative | D10: Yes | E10: Yes | F10: Yes | G10: Yes | H10: Can't tell | I10: Yes | J10: Yes | K10: =IF(OR(D10<>"Yes",E10<>"Yes"),"",COUNTIF(F10:J10,"Yes")) -> 4 | L10: Engagement evidence from teacher interviews (qualitative component appraised). 1.3 coded by a single rater; quotes support interpretation.
A11: 10 | B11: An integrated VR/AR framework for user-centric interactive experience of cultural heritage: The ArkaeVision project | C11: Quantitative descriptive | D11: Yes | E11: Yes | F11: Yes | G11: Can't tell | H11: No | I11: Yes | J11: Yes | K11: =IF(OR(D11<>"Yes",E11<>"Yes"),"",COUNTIF(F11:J11,"Yes")) -> 3 | L11: 4.1 museum visitors = target public; 4.2 opportunistic visitors, mostly adults; 4.3 author-made questionnaire, no psychometrics; 4.4 few refusals, complete forms; 4.5 descriptive %.
A12: 11 | B12: Development of practical tasks in physics with elements of augmented reality for secondary educational institutions | C12: Quantitative descriptive | D12: Yes | E12: Yes | F12: Yes | G12: Can't tell | H12: No | I12: Can't tell | J12: No | K12: =IF(OR(D12<>"Yes",E12<>"Yes"),"",COUNTIF(F12:J12,"Yes")) -> 1 | L12: 4.3 single question; 4.5 reported percentages impossible for n = 20.
A13: 12 | B13: Virtual Reality in Music Education: A Qualitative User Study of HarmosphereVR | C13: Qualitative | D13: Yes | E13: Yes | F13: Yes | G13: Can't tell | H13: Can't tell | I13: Yes | J13: Can't tell | K13: =IF(OR(D13<>"Yes",E13<>"Yes"),"",COUNTIF(F13:J13,"Yes")) -> 2 | L13: Observation notes, reaction cards and interviews; analysis ('thematic clusters') only briefly described; quotes support claims; snowball sample of 6.
A14: 13 | B14: Research on the Impact of Interactive Experience and Perceived Value on User Satisfaction in VR Education | C14: Quantitative descriptive | D14: Yes | E14: Yes | F14: Yes | G14: Yes | H14: Yes | I14: Can't tell | J14: No | K14: =IF(OR(D14<>"Yes",E14<>"Yes"),"",COUNTIF(F14:J14,"Yes")) -> 3 | L14: 4.2 random selection from 17 classes; 4.3 α and CFA reported; 4.4 distributed/collected numbers inconsistent; 4.5 hypothesised paths never reported.
A15: 14 | B15: Usability Study of GenAI for English Learning in VR | C15: Quantitative descriptive | D15: Yes | E15: Yes | F15: Yes | G15: No | H15: Yes | I15: Can't tell | J15: Yes | K15: =IF(OR(D15<>"Yes",E15<>"Yes"),"",COUNTIF(F15:J15,"Yes")) -> 3 | L15: 4.2 purposive n = 7; 4.3 standard SUS; 4.5 SUS scoring appropriate.
A16: 15 | B16: StellarScape: Explore the Solar System with AR Cube | C16: Not appraisable (no empirical learner study) | D16: Yes | E16: No | K16: =IF(OR(D16<>"Yes",E16<>"Yes"),"",COUNTIF(F16:J16,"Yes")) | L16: Development paper; no evaluation.
A17: 16 | B17: CuriosityXR: Context-aware Education Experiences with Mixed Reality and Conversation AI | C17: Quantitative non-randomised | D17: Yes | E17: Yes | F17: No | G17: No | H17: Can't tell | I17: No | J17: Can't tell | K17: =IF(OR(D17<>"Yes",E17<>"Yes"),"",COUNTIF(F17:J17,"Yes")) -> 0 | L17: 3.1 six university participants; 3.2 ratings from transcription notes, no validated measure; 3.3 not reported; 3.4 fixed order MR→laptop, no control of order/prior knowledge; 3.5 not described.
A18: 17 | B18: Cross-Reality Interaction and Collaboration in Museums, Education, and Rehabilitation | C18: Quantitative non-randomised | D18: Yes | E18: Yes | F18: No | G18: Yes | H18: Yes | I18: Can't tell | J18: Yes | K18: =IF(OR(D18<>"Yes",E18<>"Yes"),"",COUNTIF(F18:J18,"Yes")) -> 3 | L18: 3.1 six young adults, not target learners; 3.2 standard SUS/UEQ-S; 3.3 all 36 sets collected; 3.4 order/role effects not described; 3.5 sessions as planned.
A19: 18 | B19: Shrink or grow the kids? Scale cognition in an immersive virtual environment for K-12 summer camp | C19: Quantitative descriptive | D19: Yes | E19: Yes | F19: Yes | G19: Can't tell | H19: No | I19: Yes | J19: Yes | K19: =IF(OR(D19<>"Yes",E19<>"Yes"),"",COUNTIF(F19:J19,"Yes")) -> 3 | L19: 4.2 summer-camp attendees; 4.3 single author-made items; 4.4 all 69 responded; 4.5 descriptive %.
A20: 19 | B20: WEBARIO: A Web based Portal with Revolutionary Virtual Classroom and Augmented Reality Integration for Enhanced Learning | C20: Not appraisable (no empirical learner study) | D20: Yes | E20: No | K20: =IF(OR(D20<>"Yes",E20<>"Yes"),"",COUNTIF(F20:J20,"Yes")) | L20: Development paper; no evaluation.
A21: 20 | B21: Virtual learner experience (VLX): A new dimension of virtual reality environments for the assessment of knowledge transfer | C21: Quantitative descriptive | D21: Yes | E21: Yes | F21: Yes | G21: No | H21: Can't tell | I21: Can't tell | J21: Yes | K21: =IF(OR(D21<>"Yes",E21<>"Yes"),"",COUNTIF(F21:J21,"Yes")) -> 2 | L21: 4.2 convenience sample of 10; 4.3 author-made Likert items, no psychometrics; 4.4 some items not answered by all; 4.5 descriptive means.
A22: 21 | B22: GIS-BASED EDUCATIONAL GAME THROUGH LOW-COST VIRTUAL TOUR EXPERIENCE Khan Game | C22: Not appraisable (no empirical learner study) | D22: Yes | E22: No | K22: =IF(OR(D22<>"Yes",E22<>"Yes"),"",COUNTIF(F22:J22,"Yes")) | L22: Playtest mentioned but no results reported.
A23: 22 | B23: The Application of Scientific Games by Artificial Intelligence in Preschool Education under the Smart City | C23: Not appraisable (no empirical learner study) | D23: No | E23: No | K23: =IF(OR(D23<>"Yes",E23<>"Yes"),"",COUNTIF(F23:J23,"Yes")) | L23: Retracted article – not appraised.
A24: 23 | B24: arPcTECHture' - a gamified educational 3D virtual world for introductory concepts in computer architecture | C24: Quantitative descriptive | D24: Yes | E24: Yes | F24: Yes | G24: No | H24: Yes | I24: No | J24: Yes | K24: =IF(OR(D24<>"Yes",E24<>"Yes"),"",COUNTIF(F24:J24,"Yes")) -> 3 | L24: 4.3 standard UEQ, translated per guidelines; 4.4 12 of 200 responded (6%); 4.5 UEQ tool and benchmark appropriate.
A25: 24 | B25: TEACHING EARTH SYSTEMS BEYOND THE CLASSROOM: DEVELOPING A MIXED REALITY (XR) SANDBOX | C25: Not appraisable (no empirical learner study) | D25: Yes | E25: No | K25: =IF(OR(D25<>"Yes",E25<>"Yes"),"",COUNTIF(F25:J25,"Yes")) | L25: No user data received.
A26: 25 | B26: Fantastic voyage 2021: Using interactive VR storytelling to explain targeted COVID-19 vaccine delivery to antigen-presenting cells | C26: Not appraisable (no empirical learner study) | D26: Yes | E26: No | K26: =IF(OR(D26<>"Yes",E26<>"Yes"),"",COUNTIF(F26:J26,"Yes")) | L26: Design paper; no evaluation.
A27: 26 | B27: Design and implementation of a virtual reality insects learning system with its user experience evaluation | C27: Quantitative descriptive | D27: Yes | E27: Yes | F27: Yes | G27: Can't tell | H27: Yes | I27: Can't tell | J27: Yes | K27: =IF(OR(D27<>"Yes",E27<>"Yes"),"",COUNTIF(F27:J27,"Yes")) -> 3 | L27: 4.3 adapted scales with α ≥ .74 (but load items worded as ease); 4.4 completion not reported (gift incentive); 4.5 descriptive + correlations appropriate.
A28: 27 | B28: Virtual reality for deeper learning: An exemplar from high school science | C28: Qualitative | D28: Yes | E28: Yes | F28: Yes | G28: Yes | H28: Can't tell | I28: Yes | J28: Can't tell | K28: =IF(OR(D28<>"Yes",E28<>"Yes"),"",COUNTIF(F28:J28,"Yes")) -> 3 | L28: Rich video/work-sample data; exemplar purposively selected as most successful case, analysis process not detailed.
A29: 28 | B29: Virtual simulation for history education | C29: Not appraisable (no empirical learner study) | D29: Yes | E29: No | K29: =IF(OR(D29<>"Yes",E29<>"Yes"),"",COUNTIF(F29:J29,"Yes")) | L29: Practice description; no data.
A30: 29 | B30: Teach Me a Story: An Augmented Reality Application for Teaching History in Middle School | C30: Quantitative non-randomised | D30: Yes | E30: Yes | F30: Can't tell | G30: No | H30: Yes | I30: No | J30: Yes | K30: =IF(OR(D30<>"Yes",E30<>"Yes"),"",COUNTIF(F30:J30,"Yes")) -> 2 | L30: 3.2 author-made 4-point items, comparison with 'expected' time not measured; 3.3 all 26 completed; 3.4 no control of confounders; 3.5 lesson delivered as planned.
A31: 30 | B31: An immersive virtual reality learning environment with CFD simulations: Unveiling the Virtual Garage concept | C31: Quantitative descriptive | D31: Yes | E31: Yes | F31: Yes | G31: Can't tell | H31: Yes | I31: Yes | J31: Yes | K31: =IF(OR(D31<>"Yes",E31<>"Yes"),"",COUNTIF(F31:J31,"Yes")) -> 4 | L31: 4.3 SUS, UEQ, NASA-TLX, SSQ standard; 4.4 no drop-outs; 4.5 appropriate non-parametric tests.
A32: 31 | B32: Gamified Virtual Reality for Computational Thinking | C32: Quantitative non-randomised | D32: Yes | E32: Yes | F32: Can't tell | G32: Yes | H32: Yes | I32: Yes | J32: Yes | K32: =IF(OR(D32<>"Yes",E32<>"Yes"),"",COUNTIF(F32:J32,"Yes")) -> 4 | L32: 3.1 interns + adults, n = 8; 3.2 standard UEQ and presence scale; 3.3 all completed; 3.4 pseudorandom order, task pre-explained; 3.5 as planned.
A33: 32 | B33: Sustainability in Elementary School: The Prototype and Evaluation of XR-based Learning to Achieve Quality Education | C33: Quantitative descriptive | D33: Yes | E33: Yes | F33: Yes | G33: No | H33: Yes | I33: Can't tell | J33: Yes | K33: =IF(OR(D33<>"Yes",E33<>"Yes"),"",COUNTIF(F33:J33,"Yes")) -> 3 | L33: 4.2 purposive, one private school; 4.3 standard UEQ; 4.4 50 → 40 after cleaning; 4.5 UEQ tool.
A34: 33 | B34: Virtual Reality-Based Traffic Sign Education for Early Childhood | C34: Quantitative descriptive | D34: Yes | E34: Yes | F34: Yes | G34: Can't tell | H34: No | I34: Can't tell | J34: Yes | K34: =IF(OR(D34<>"Yes",E34<>"Yes"),"",COUNTIF(F34:J34,"Yes")) -> 2 | L34: 4.3 single author-made rating items with 4–7-year-olds; 4.5 descriptive counts.
A35: 34 | B35: A new intelligent VR biological learning system based on natural interaction | C35: Quantitative non-randomised | D35: Yes | E35: Yes | F35: Can't tell | G35: No | H35: Can't tell | I35: No | J35: Can't tell | K35: =IF(OR(D35<>"Yes",E35<>"Yes"),"",COUNTIF(F35:J35,"Yes")) -> 0 | L35: Participants undescribed; author-made questionnaire; order and confounders not addressed; procedure unclear.
A36: 35 | B36: Exploring User Experience and Usability in a Metaverse Learning Environment for Students: A Usability Study of the Artificial Intelligence, Innovation, and Society (AIIS) | C36: Quantitative descriptive | D36: Yes | E36: Yes | F36: Yes | G36: No | H36: Yes | I36: Can't tell | J36: Yes | K36: =IF(OR(D36<>"Yes",E36<>"Yes"),"",COUNTIF(F36:J36,"Yes")) -> 3 | L36: 4.2 social-media recruitment; 4.3 standard GEQ; 4.5 descriptive means.
A37: 36 | B37: Exploring Prehistoric Era in Virtual Reality Walkthrough | C37: Quantitative descriptive | D37: Yes | E37: Yes | F37: Can't tell | G37: Can't tell | H37: No | I37: No | J37: No | K37: =IF(OR(D37<>"Yes",E37<>"Yes"),"",COUNTIF(F37:J37,"Yes")) -> 0 | L37: N not stated; author-made acceptance items; item counts differ (missing responses); reported % inconsistent with figure.
A38: 37 | B38: Chemisim: A Web-based VR Simulator for Chemistry Experiments | C38: Quantitative descriptive | D38: Yes | E38: Yes | F38: No | G38: No | H38: No | I38: Can't tell | J38: Yes | K38: =IF(OR(D38<>"Yes",E38<>"Yes"),"",COUNTIF(F38:J38,"Yes")) -> 1 | L38: Intended for high-school students but tested with university students/professors; author-made ratings; descriptive means.
A39: 38 | B39: Multidisciplinary Virtual Environments for Kids with ADHD: A Pilot Study | C39: Quantitative non-randomised | D39: Yes | E39: Yes | F39: Yes | G39: No | H39: Yes | I39: No | J39: Can't tell | K39: =IF(OR(D39<>"Yes",E39<>"Yes"),"",COUNTIF(F39:J39,"Yes")) -> 2 | L39: 3.1 children with ADHD = target; 3.2 post-test α = .68, teacher-rated; 3.3 all 5 completed; 3.4 no control; 3.5 exposure not described.
A40: 39 | B40: vSocial: a cloud-based system for social virtual reality learning environment applications in special education | C40: Quantitative non-randomised | D40: Yes | E40: Yes | F40: No | G40: No | H40: Can't tell | I40: Yes | J40: Can't tell | K40: =IF(OR(D40<>"Yes",E40<>"Yes"),"",COUNTIF(F40:J40,"Yes")) -> 1 | L40: 3.1 comparison run with college students, not ASD youth; 3.2 author-made survey; 3.4 order randomised; others not reported.
...

Sheet Sheet1
A1: New num | C1: Authors | D1: Author full names | E1: Author(s) ID | F1: Title | G1: Year | H1: Source title | I1: Cited by | J1: DOI | K1: Link | L1: Affiliations | M1: Authors with affiliations | N1: Abstract | O1: Author Keywords | P1: Index Keywords | Q1: Publisher | R1: Language of Original Document | S1: Document Type | T1: Publication Stage | U1: Open Access | V1: Source | W1: Status | X1: Reason | Y1: Degree level | Z1: Who 1 | AA1: Who 2 | AB1: Note 1 | AC1: Note 2 | AD1: RQ1 | AE1: RQ2 | AF1: RQ3 | AG1: RQ2 | AH1: RQ4 | AL1: Focus | AM1: Who checked GPT Feedback | AN1: Note 1 | AO1: Who Re checked GPT Feedback | AP1: Main Author | AQ1: Main Author Email | AR1: RQ5 – Country (study site) | AS1: RQ5 – Region | AT1: RQ5 – Education level (ISCED 2011) | AU1: RQ5 – Learner population | AV1: RQ5 – Subject area (ISCED-F 2013 broad field) | AW1: RQ5 – Subject (specific) | AX1: RQ6 – XR type | AY1: RQ6 – Device category | AZ1: RQ6 – Device (specific) | BA1: RQ6 – Comparison condition | BB1: RQ6 – Engagement effect | BC1: RQ6 – Motivation effect | BD1: RQ6 – Satisfaction effect | BE1: RQ6 – Other reported outcomes | BF1: RQ6 – Statistical support | BG1: RQ6 – Effect size | BH1: RQ6 – Instrument(s) | BI1: RQ6 – Instrument validated? | BJ1: RQ7 – Study design | BK1: RQ7 – Design class | BL1: RQ7 – MMAT category | BM1: RQ7 – Sample size (N) | BN1: RQ7 – Exposure (duration) | BO1: RQ7 – MMAT score (0–5) | BP1: RQ7 – Overall rigor (auto) | BQ1: RQ7 – Adverse effects / limitations reported | BR1: RQ7 – Adverse-effect reporting | BS1: Synthesis set | BT1: Eligibility reason | BU1: Extraction status | BV1: Verification flags
A2: 1 | C2: Chew C.S.; Zafarin M.N.S.; Zain N.H.M.; Aminuddin R.; Tan T.G.; Chin K.O. | D2: Chew, Chiou Sheng (57206205702); Zafarin, Muhammad Nabil Shah (59664996100); Zain, Nurul Hidayah Mat (59664977600); Aminuddin, Raihah (57189037041); Tan, Tse Guan (57226387853); Chin, Kim On (59484027400) | E2: 57206205702; 59664996100; 59664977600; 57189037041; 57226387853; 59484027400 | F2: Transforming Secondary School Chemistry Learning with Virtual Reality | G2: 2024 | H2: 2024 IEEE 22nd Student Conference on Research and Development, SCOReD 2024 | I2: 0 | J2: 10.1109/SCOReD64708.2024.10872679 | K2: https://www.scopus.com/inward/record.uri?eid=2-s2.0-85219552594&doi=10.1109%2fSCOReD64708.2024.10872679&partnerID=40&md5=187cbbb42c76a164a4f1ddcf9e3eaf41 | L2: Universiti Teknologi MARA Melaka Branch, College of Computing, Informatics and Mathematics, Jasin Campus, Melaka, Malaysia; Universiti Malaysia Kelantan, Faculty of Creative Technology and Heritage, Malaysia; Universiti Malaysia Sabah, Faculty of Computing and Informatics, Sabah, Malaysia | M2: Chew C.S., Universiti Teknologi MARA Melaka Branch, College of Computing, Informatics and Mathematics, Jasin Campus, Melaka, Malaysia; Zafarin M.N.S., Universiti Teknologi MARA Melaka Branch, College of Computing, Informatics and Mathematics, Jasin Campus, Melaka, Malaysia; Zain N.H.M., Universiti Teknologi MARA Melaka Branch, College of Computing, Informatics and Mathematics, Jasin Campus, Melaka, Malaysia; Aminuddin R., Universiti Teknologi MARA Melaka Branch, College of Computing, Informatics and Mathematics, Jasin Campus, Melaka, Malaysia; Tan T.G., Universiti Malaysia Kelantan, Faculty of Creative Technology and Heritage, Malaysia; Chin K.O., Universiti Malaysia Sabah, Faculty of Computing and Informatics, Sabah, Malaysia | N2: In secondary schools, traditional chemistry instruction often depends on lecture-based approaches and occasional hands-on experiments, which may limit students' grasp of complex concepts like chemical reactions and molecular behaviour. This study addresses the need for enhanced educational tools by introducing a Virtual Reality (VR) application designed to enrich chemistry learning through immersive, interactive experiences. The VR tool allows students to simulate chemical reactions with adjustable parameters, such as temperature and concentration, enabling safe, hands-on exploration of complex processes. Usability was assessed among 30 secondary school students in Malaysia using the System Usability Scale (SUS), a standardized measure that gauges user experience across factors like functionality and ease of use. Findings showed a strong average SUS score of 91.25, indicating high usability and positive engagement from users. These results suggest that incorporating VR into the chemistry curriculum can help make challenging topics more accessible and engaging, supporting the modernization of science education. Future studies will look to expand the sample size and investigate additional chemistry topics to validate the tool's educational benefits further. © 2024 IEEE. | O2: Chemistry; Immersive learning; Secondary education; Virtual reality | P2: Complexation; Adjustable parameters; Educational tools; Immersive; Immersive learning; Molecular behavior; Reaction behavior; Secondary education; Secondary schools; System usability; Virtual reality tools; Students | Q2: Institute of Electrical and Electronics Engineers Inc. | R2: English | S2: Conference paper | T2: Final | V2: Scopus | W2: Accepted | X2: Relevant | Y2: Basic education | Z2: Ahsan | AA2: Lamarck | AC2: Check | AD2: Device used: Oculus Quest 2 standalone VR headset​ Type of XR: Fully immersive Virtual Reality (VR) (interactive 3D environment) | AE2: System Usability Scale (SUS)​: 10-question survey evaluating ease of use, efficiency, and satisfaction. | AF2: Students: Found VR easy to use and highly engaging​ Helped with understanding difficult concepts like reaction rates. No mention of negative effects like motion sickness in this study​ Teachers: Not directly evaluated here, but VR was framed as a helpful complement to traditional methods​ | AG2: Metric: SUS Score (System Usability Scale)​ Method:SUS processed by: Reversing odd questions, adjusting even questions. Summing and scaling to 0–100. Result: Average SUS Score: 91.25, indicating excellent usability​ | AH2: Software/Platform: Unity for VR environment development​ Hardware: Oculus Quest 2 headset​ Instructional design: ADDIE model (Analysis, Design, Development, Implementation, Evaluation) for systematic educational tool creation​ | AL2: STEM | AM2: Ahsan | AN2: Check | AO2: Lamarck | AR2: Malaysia | AS2: Asia | AT2: Upper secondary | AU2: Typical learners (age 16) | AV2: Natural sciences, mathematics & statistics | AW2: Chemistry (chemical reactions) | AX2: VR | AY2: HMD (immersive) | AZ2: HMD – standalone | BA2: None | BB2: Not measured | BC2: Not measured | BD2: Not measured | BE2: Usability only: SUS = 91.25. Authors state engagement and learning were NOT evaluated | BF2: Descriptive only | BG2: Not reported | BH2: SUS (items modified by authors) | BI2: Adapted | BJ2: Single-group post-test only | BK2: Single group, post-test only | BL2: Quantitative descriptive | BM2: 30 students (age 16; 60% F) | BN2: Single session (duration NR) | BO2: =IF(COUNTIF('MMAT Appraisal'!$A$2:$A$60,A2)=0,"",INDEX('MMAT Appraisal'!$K$2:$K$60,MATCH(A2,'MMAT Appraisal'!$A$2:$A$60,0))) -> 2 | BP2: =IF(OR(BF2="No empirical data",ISNUMBER(SEARCH("RETRACTED",BV2))),"Not rated",IF(AND(ISNUMBER(BO2),BO2<=2),"Low",IF(AND(OR(BJ2="RCT",BJ2="Quasi-experimental with control"),LEFT(BF2,11)="Inferential",OR(BI2="Yes",BI2="Partly"),OR(BO2="",BO2>=4)),"High",IF(OR(BA2<>"None",LEFT(BF2,11)="Inferential"),"Moderate","Low")))) -> Low | BQ2: Not reported | BR2: Not reported | BS2: Excluded | BT2: E3: No engagement, motivation or satisfaction outcome measured (usability only; authors state engagement was not evaluated) | BU2: Verified (full text) | BV2: Abstract claims 'positive engagement', but the paper says engagement was not evaluated – no E/M/S evidence
A3: 2 | C3: Cheng K.-H. | D3: Cheng, Kun-Hung (37461088800) | E3: 37461088800 | F3: Development of an immersive virtual reality system for learning about plants in primary education: evaluation of teachers’ perceptions and learners’ flow experiences and learning attitudes | G3: 2024 | H3: Educational Technology Research and Development | I3: 6 | J3: 10.1007/s11423-023-10300-6 | K3: https://www.scopus.com/inward/record.uri?eid=2-s2.0-85174240307&doi=10.1007%2fs11423-023-10300-6&partnerID=40&md5=d42e39e94437a741283692aedd7cf464 | L3: Graduate Institute of Library & amp; Information Science, National Chung Hsing University, 145 Xingda Rd., South District, Taichung, 402, Taiwan; Innovation and Development Center of Sustainable Agriculture, National Chung Hsing University, Taichung, Taiwan | M3: Cheng K.-H., Graduate Institute of Library & amp; Information Science, National Chung Hsing University, 145 Xingda Rd., South District, Taichung, 402, Taiwan, Innovation and Development Center of Sustainable Agriculture, National Chung Hsing University, Taichung, Taiwan | N3: This study aimed to establish a fully 3D modeled immersive virtual reality (IVR) system for primary school students learning about plants and evaluate teachers’ perceptions of the usage of the system and pupils’ flow experiences and learning attitudes. There were 5 teachers with expertise in science and IVR experience who were first interviewed to understand their consideration of the limitations of teaching about plants in the classroom. The framework and script of the learning content for the IVR system, as well as the user interface and function were then comprehensively described. Another 10 teachers were invited to evaluate the appropriateness of the system for fifth-grade students to learn about plants. These teachers generally expressed positive attitudes towards exploiting the IVR system for their teaching. Moreover, there were 37 fifth-grade students contributed to the evaluation of the system. The results indicated that the IVR system was capable of offering the pupils perceptions of antecedences to achieve flow such as task challenge, clear goal, instant feedback, well control, and playability, and aroused their flow experiences, particularly regarding autotelic experience and concentration. This study also verified the relationships between the pupils’ flow experiences and learning attitudes. The crucial roles of flow perceptions including playability, challenge, and autotelic experience in the pupils’ learning attitudes were further identified. According to the results of the evaluation from the teachers’ and students’ perspectives, several practical and academic implications of this study are proposed. © Association for Educational Communications and Technology 2023. | O3: Attitude; Flow experience; Instructional design; Science learning; Virtual reality | Q3: Springer | R3: English | S3: Article | T3: Final | V3: Scopus | W3: Accepted | X3: Relevant | Y3: Basic education | Z3: Ahsan | AA3: Lamarck | AC3: Check | AD3: Device used: Standalone VR Headset: Gear VR with controller​ Type of XR: Fully 3D modeled immersive virtual reality (IVR) — not 360° photos. Environment: Custom Unity-based 3D environments with interactive elements​ | AE3: Surveys: Flow Scale for Games (FSG) (adapted) — measuring flow antecedents and flow experiences​ . Learning Attitude Survey — measuring ease of use, usefulness, affection (negative feelings), and intention​ . Interviews: Teachers interviewed after trials regarding usability, suitability, and willingness to use | AF3: Students: Increased concentration, intrinsic enjoyment (autotelic experience), and positive attitudes. Minor issues: moderate time distortion, mild self-consciousness, but mostly positive​ . Teachers: Mostly positive (seeing VR as beneficial), but some discomfort (motion sickness, getting used to panoramic vision) and concerns about time demands | AG3: Metrics for Students: Flow antecedents: challenge, goal clarity, feedback, control, playability. Flow experiences: concentration, time distortion, autotelic experience (enjoyment), loss of self-consciousness​ . Learning attitudes: ease of use, usefulness, affection (anxiety/boredom), intention to reuse​ . Statistical Analyses: Repeated-measures ANOVA and Stepwise Regression Analysis | AH3: Software/Platform: Unity (game engine) for VR environment development​ . Maya for 3D modeling and animation​ . Oculus Mobile SDK for VR integration​ . Hardware: Gear VR headset + Controller​ . Instructional design method: ADDIE model (Analysis, Design, Development, Implementation, Evaluation) | AL3: STEM | AM3: Joao | AN3: Check | AO3: Pedro | AR3: Taiwan | AS3: Asia | AT3: Primary | AU3: Typical learners (grade 5) + teachers | AV3: Natural sciences, mathematics & statistics | AW3: Biology (plants), grade 5 | AX3: VR | AY3: HMD (immersive) | AZ3: HMD – mobile (Gear VR) | BA3: None | BB3: + | BC3: + | BD3: Not measured | BE3: Concentration M = 4.38, autotelic enjoyment M = 4.49, intention to reuse M = 4.54 (/5); low anxiety/boredom M = 1.80 | BF3: Inferential, no effect size | BG3: No XR-vs-control ES (single group); R² = .14–.48 for flow → attitude regressions | BH3: Flow Scale for Games (Kiili 2006, adapted; subscale α = .54–.82, overall .90); learning-attitude survey (adapted; α = .73) | BI3: Adapted | BJ3: Mixed methods (single group) | BK3: Single group, mixed methods / DBR | BL3: Quantitative descriptive | BM3: 37 grade-5 students (19 M, 18 F); 10 teachers (+5 interviewed in analysis phase) | BN3: Single session, 15–20 min | BO3: =IF(COUNTIF('MMAT Appraisal'!$A$2:$A$60,A3)=0,"",INDEX('MMAT Appraisal'!$K$2:$K$60,MATCH(A3,'MMAT Appraisal'!$A$2:$A$60,0))) -> 3 | BP3: =IF(OR(BF3="No empirical data",ISNUMBER(SEARCH("RETRACTED",BV3))),"Not rated",IF(AND(ISNUMBER(BO3),BO3<=2),"Low",IF(AND(OR(BJ3="RCT",BJ3="Quasi-experimental with control"),LEFT(BF3,11)="Inferential",OR(BI3="Yes",BI3="Partly"),OR(BO3="",BO3>=4)),"High",IF(OR(BA3<>"None",LEFT(BF3,11)="Inferential"),"Moderate","Low")))) -> Moderate | BQ3: Teachers: loss of spatial sense, one case of motion sickness; none reported for students | BR3: Cybersickness / physical discomfort reported | BS3: Core | BT3: Basic-education learners with empirical E/M/S data | BU3: Verified (full text) | BV3: Mixed-methods study; MMAT applied to the student survey component that gives the RQ6 evidence
A4: 3 | C4: Dash A.K.; Behera S.K.; Dogra D.P. | D4: Dash, Ajaya Kumar (56723571400); Behera, Santosh Kumar (57220715678); Dogra, Debi Prosad (35408975400) | E4: 56723571400; 57220715678; 35408975400 | F4: PlutoAR: a scalable marker-based augmented reality application for interactive and inclusive education | G4: 2024 | H4: Multimedia Tools and Applications | I4: 1 | J4: 10.1007/s11042-023-17756-x | K4: https://www.scopus.com/inward/record.uri?eid=2-s2.0-85179311876&doi=10.1007%2fs11042-023-17756-x&partnerID=40&md5=1173b72cd0c5cc55d1d20e7a1500440b | L4: Department of CSE, International Institute of Information Technology Bhubaneswar, Gothapatna, Odisha, Bhubaneswar, 751003, India; School of Electrical Sciences, Indian Institute of Technology Bhubaneswar, Argul, Odisha, Khordha, 752050, India; Department of CSE, National Institute of Technology, Kerala, Calicut, 673601, India | M4: Dash A.K., Department of CSE, International Institute of Information Technology Bhubaneswar, Gothapatna, Odisha, Bhubaneswar, 751003, India, School of Electrical Sciences, Indian Institute of Technology Bhubaneswar, Argul, Odisha, Khordha, 752050, India; Behera S.K., Department of CSE, National Institute of Technology, Kerala, Calicut, 673601, India; Dogra D.P., School of Electrical Sciences, Indian Institute of Technology Bhubaneswar, Argul, Odisha, Khordha, 752050, India | N4: Various studies have suggested that computational thinking needs to be highlighted as one of the essential abilities and it should be taught in the standard K-10 curriculum. However, the standard K-10 curriculum does not always contain accessible technology that uses interactive teaching methods and efficient analytical skill development. Also, most practical computational thinking applications that are being created seem to be complex and expensive for educational settings. In this work, we introduce PlutoAR, a marker-based augmented reality (AR) interpreter that is scalable, inexpensive, portable, and can be used as a platform for kids to enhance their skills in an inclusive way. PlutoAR incorporates AR through an interactive toolkit to give students the experiences of both the real and virtual worlds, overcoming the limitations of traditional and non-interactive setups. With the help of technology-based solutions, this effort intends to enable students from all demographic groups to engage in the learning process, regardless of their level of competence. The PlutoAR mobile application presently runs on any Android device with a camera. It creates inbuilt AR experiences like stories, basic elementary mathematics, navigating mazes utilising conditional loops to solve them, and the intuition of gravity. The usability of the PutoAR application is verified by performing the qualitative and quantitative analysis through user feedback. The application seems to be acceptable by users with a System Usability Scale (SUS) score of more than 80. In future, we intend to provide flexibility to the user for adding new content inside the application whenever needed and to promote AR-based collaboration among the students. © The Author(s), under exclusive licence to Springer Science+Business Media, LLC, part of Springer Nature 2023. | O4: Augmented reality; K-10 education; Smart learning application; User interfaces | P4: Augmented reality; Curricula; Learning systems; Students; Virtual reality; Analytical skills; Augmented reality applications; Computational thinkings; Essential abilities; Inclusive education; Interactive education; K-10 education; Skills development; Smart learning application; Teaching methods; User interfaces | Q4: Springer | R4: English | S4: Article | T4: Final | V4: Scopus | W4: Accepted | X4: Relevant | Y4: Basic education | Z4: Ahsan | AA4: Lamarck | AC4: Check | AD4: Device used: Any Android mobile device with a camera​ . Type of XR: Marker-based Augmented Reality (AR), not full VR or Cave​ | AE4: System Usability Scale (SUS)​ : Standard 10-question SUS survey (Likert scale 1–5). Custom Survey Questions for qualitative analysis​ : Evaluated ease of use, understanding concepts, visualization quality, 3D object quality, portability, overall experience. | AF4: Students: Reported high motivation, ease of use, better visualization of concepts​ . Encouraged exploration, algorithmic thinking, and problem-solving. Teachers: Reported better engagement, especially in special needs students​ | AG4: Metrics: SUS Score (System Usability Scale). Cronbach’s alpha to validate survey consistency (α = 0.770, "acceptable")​ . Results: Average SUS score: ~83–86 depending on age group, meaning excellent usability​ | AH4: oftware/Platform: Unity 3D for AR app development​ . Vuforia Engine for marker-based AR​ . Android Studio for mobile app deployment​ . Hardware: Android smartphones/tablets. Markers: Special printed tiles ("DreamKit") placed on a Launchpad (A4 paper) to trigger 3D AR content​ | AL4: STEM | AM4: Lamarck | AN4: Check | AO4: Ahsan | AR4: India | AS4: Asia | AT4: Mixed (school-age + adults) | AU4: School visitors & event participants aged 10–45 (70% aged 10–15) | AV4: ICT | AW4: Computational thinking; elementary maths & science facts | AX4: AR | AY4: Handheld (mobile/tablet) | AZ4: Mobile/tablet – marker-based AR | BA4: None | BB4: Not measured | BC4: Not measured | BD4: + | BE4: Overall experience rated ≥ 7/10 by ~85%; ease of use ≥ 7/10 by ~80%; SUS ≈ 83 (age 10–15), 'excellent' across age groups | BF4: Descriptive only | BG4: Not reported | BH4: Author-made 6-item survey (α = .77); SUS (standard) | BI4: Partly | BJ4: Single-group post-test only | BK4: Single group, post-test only | BL4: Quantitative descriptive | BM4: 415 participants (289 aged 10–15) | BN4: Demonstration sessions (duration NR) | BO4: =IF(COUNTIF('MMAT Appraisal'!$A$2:$A$60,A4)=0,"",INDEX('MMAT Appraisal'!$K$2:$K$60,MATCH(A4,'MMAT Appraisal'!$A$2:$A$60,0))) -> 1 | BP4: =IF(OR(BF4="No empirical data",ISNUMBER(SEARCH("RETRACTED",BV4))),"Not rated",IF(AND(ISNUMBER(BO4),BO4<=2),"Low",IF(AND(OR(BJ4="RCT",BJ4="Quasi-experimental with control"),LEFT(BF4,11)="Inferential",OR(BI4="Yes",BI4="Partly"),OR(BO4="",BO4>=4)),"High",IF(OR(BA4<>"None",LEFT(BF4,11)="Inferential"),"Moderate","Low")))) -> Low | BQ4: None reported; marker dependency noted | BR4: Explicitly none observed | BS4: Core | BT4: Basic-education learners with empirical E/M/S data | BU4: Verified (full text) | BV4: Children and adults pooled; SEN school visit is anecdotal observation only; engagement/motivation claimed but not measured
